Exception in thread Thread-1 (monitor_worker):
Traceback (most recent call last):
  File "C:\Users\79533\PycharmProjects\DriveApp\.venv\Lib\site-packages\tenacity\__init__.py", line 382, in __call__
    result = fn(*args, **kwargs)
             ^^^^^^^^^^^^^^^^^^^
  File "C:\Users\79533\PycharmProjects\DriveApp\drive_service.py", line 53, in list_files_in_folder
    results = service.files().list(q=query, fields="files(id, name)").execute()
              ^^^^^^^^^^^^^^^^^^^^^^^^^^^^^^^^^^^^^^^^^^^^^^^^^^^^^^^^^^^^^^^^^
  File "C:\Users\79533\PycharmProjects\DriveApp\.venv\Lib\site-packages\googleapiclient\_helpers.py", line 130, in positional_wrapper
    return wrapped(*args, **kwargs)
           ^^^^^^^^^^^^^^^^^^^^^^^^
  File "C:\Users\79533\PycharmProjects\DriveApp\.venv\Lib\site-packages\googleapiclient\http.py", line 923, in execute
    resp, content = _retry_request(
                    ^^^^^^^^^^^^^^^
  File "C:\Users\79533\PycharmProjects\DriveApp\.venv\Lib\site-packages\googleapiclient\http.py", line 191, in _retry_request
    resp, content = http.request(uri, method, *args, **kwargs)
                    ^^^^^^^^^^^^^^^^^^^^^^^^^^^^^^^^^^^^^^^^^^
  File "C:\Users\79533\PycharmProjects\DriveApp\.venv\Lib\site-packages\google_auth_httplib2.py", line 209, in request
    self.credentials.before_request(self._request, method, uri, request_headers)
  File "C:\Users\79533\PycharmProjects\DriveApp\.venv\Lib\site-packages\google\auth\credentials.py", line 135, in before_request
    self.refresh(request)
  File "C:\Users\79533\PycharmProjects\DriveApp\.venv\Lib\site-packages\google\oauth2\service_account.py", line 429, in refresh
    access_token, expiry, _ = _client.jwt_grant(
                              ^^^^^^^^^^^^^^^^^^
  File "C:\Users\79533\PycharmProjects\DriveApp\.venv\Lib\site-packages\google\oauth2\_client.py", line 294, in jwt_grant
    response_data = _token_endpoint_request(
                    ^^^^^^^^^^^^^^^^^^^^^^^^
  File "C:\Users\79533\PycharmProjects\DriveApp\.venv\Lib\site-packages\google\oauth2\_client.py", line 265, in _token_endpoint_request
    _handle_error_response(response_data, retryable_error)
  File "C:\Users\79533\PycharmProjects\DriveApp\.venv\Lib\site-packages\google\oauth2\_client.py", line 69, in _handle_error_response
    raise exceptions.RefreshError(
google.auth.exceptions.RefreshError: ('invalid_grant: Invalid JWT: Token must be a short-lived token (60 minutes) and in a reasonable timeframe. Check your iat and exp values in the JWT claim.', {'error': 'invalid_grant', 'error_description': 'Invalid JWT: Token must be a short-lived token (60 minutes) and in a reasonable timeframe. Check your iat and exp values in the JWT claim.'})

The above exception was the direct cause of the following exception:

Traceback (most recent call last):
  File "C:\Users\79533\AppData\Local\Programs\Python\Python312\Lib\threading.py", line 1073, in _bootstrap_inner
    self.run()
  File "C:\Users\79533\AppData\Local\Programs\Python\Python312\Lib\threading.py", line 1010, in run
    self._target(*self._args, **self._kwargs)
  File "C:\Users\79533\PycharmProjects\DriveApp\gui.py", line 135, in monitor_worker
    check_monitor_tasks(log_callback)
  File "C:\Users\79533\PycharmProjects\DriveApp\gui.py", line 110, in check_monitor_tasks
    files = list_files_in_folder(source_id)
            ^^^^^^^^^^^^^^^^^^^^^^^^^^^^^^^
  File "C:\Users\79533\PycharmProjects\DriveApp\.venv\Lib\site-packages\tenacity\__init__.py", line 289, in wrapped_f
    return self(f, *args, **kw)
           ^^^^^^^^^^^^^^^^^^^^
  File "C:\Users\79533\PycharmProjects\DriveApp\.venv\Lib\site-packages\tenacity\__init__.py", line 379, in __call__
    do = self.iter(retry_state=retry_state)
         ^^^^^^^^^^^^^^^^^^^^^^^^^^^^^^^^^^
  File "C:\Users\79533\PycharmProjects\DriveApp\.venv\Lib\site-packages\tenacity\__init__.py", line 326, in iter
    raise retry_exc from fut.exception()
tenacity.RetryError: RetryError[<Future at 0x1a00a4b31d0 state=finished raised RefreshError>]
